[0m17:51:27.677021 [debug] [MainThread]: Sending event: {'category': 'dbt', 'action': 'invocation', 'label': 'start', 'context': [<snowplow_tracker.self_describing_json.SelfDescribingJson object at 0x000001F7698749D0>, <snowplow_tracker.self_describing_json.SelfDescribingJson object at 0x000001F76B73D3F0>, <snowplow_tracker.self_describing_json.SelfDescribingJson object at 0x000001F76B73D180>]}


============================== 17:51:27.683389 | 4c78dab7-c120-40f8-9aae-1dc985464346 ==============================
[0m17:51:27.683389 [info ] [MainThread]: Running with dbt=1.9.2
[0m17:51:27.685313 [debug] [MainThread]: running dbt with arguments {'printer_width': '80', 'indirect_selection': 'eager', 'log_cache_events': 'False', 'write_json': 'True', 'partial_parse': 'True', 'cache_selected_only': 'False', 'profiles_dir': 'C:\\Users\\sreej\\.dbt', 'fail_fast': 'False', 'debug': 'False', 'log_path': 'logs', 'version_check': 'True', 'warn_error': 'None', 'use_colors': 'True', 'use_experimental_parser': 'False', 'no_print': 'None', 'quiet': 'False', 'empty': 'False', 'log_format': 'default', 'invocation_command': 'dbt run', 'warn_error_options': 'WarnErrorOptions(include=[], exclude=[])', 'static_parser': 'True', 'target_path': 'None', 'introspect': 'True', 'send_anonymous_usage_stats': 'True'}
[0m17:51:27.686525 [error] [MainThread]: Encountered an error:
Runtime Error
  No dbt_project.yml found at expected path C:\Users\sreej\.dbt\dbt_project.yml
  Verify that each entry within packages.yml (and their transitive dependencies) contains a file named dbt_project.yml
  
[0m17:51:27.687765 [debug] [MainThread]: Command `dbt run` failed at 17:51:27.687141 after 0.12 seconds
[0m17:51:27.687765 [debug] [MainThread]: Sending event: {'category': 'dbt', 'action': 'invocation', 'label': 'end', 'context': [<snowplow_tracker.self_describing_json.SelfDescribingJson object at 0x000001F7698749D0>, <snowplow_tracker.self_describing_json.SelfDescribingJson object at 0x000001F76B73D180>, <snowplow_tracker.self_describing_json.SelfDescribingJson object at 0x000001F76B73D450>]}
[0m17:51:27.688343 [debug] [MainThread]: Flushing usage events
[0m17:51:28.651147 [debug] [MainThread]: An error was encountered while trying to flush usage events
[0m18:32:52.700174 [debug] [MainThread]: Sending event: {'category': 'dbt', 'action': 'invocation', 'label': 'start', 'context': [<snowplow_tracker.self_describing_json.SelfDescribingJson object at 0x000001365D9F0A90>, <snowplow_tracker.self_describing_json.SelfDescribingJson object at 0x000001365F8BD360>, <snowplow_tracker.self_describing_json.SelfDescribingJson object at 0x000001365F8BD180>]}


============================== 18:32:52.700174 | 55363286-43ad-4ab6-a190-2feaf911f419 ==============================
[0m18:32:52.700174 [info ] [MainThread]: Running with dbt=1.9.2
[0m18:32:52.700174 [debug] [MainThread]: running dbt with arguments {'printer_width': '80', 'indirect_selection': 'eager', 'log_cache_events': 'False', 'write_json': 'True', 'partial_parse': 'True', 'cache_selected_only': 'False', 'warn_error': 'None', 'fail_fast': 'False', 'debug': 'False', 'log_path': 'logs', 'version_check': 'True', 'profiles_dir': 'C:\\Users\\sreej\\.dbt', 'use_colors': 'True', 'use_experimental_parser': 'False', 'empty': 'None', 'quiet': 'False', 'no_print': 'None', 'warn_error_options': 'WarnErrorOptions(include=[], exclude=[])', 'introspect': 'True', 'log_format': 'default', 'static_parser': 'True', 'target_path': 'None', 'invocation_command': 'dbt init my_dbt_project', 'send_anonymous_usage_stats': 'True'}
[0m18:32:52.707436 [debug] [MainThread]: Starter project path: C:\Users\sreej\AppData\Local\Programs\Python\Python310\lib\site-packages\dbt\include\starter_project
[0m18:32:52.734023 [info ] [MainThread]: 
Your new dbt project "my_dbt_project" was created!

For more information on how to configure the profiles.yml file,
please consult the dbt documentation here:

  https://docs.getdbt.com/docs/configure-your-profile

One more thing:

Need help? Don't hesitate to reach out to us via GitHub issues or on Slack:

  https://community.getdbt.com/

Happy modeling!

[0m18:32:52.734023 [info ] [MainThread]: Setting up your profile.
[0m18:33:03.656324 [error] [MainThread]: Encountered an error:

[0m18:33:03.656324 [error] [MainThread]: Traceback (most recent call last):
  File "C:\Users\sreej\AppData\Local\Programs\Python\Python310\lib\site-packages\dbt\cli\requires.py", line 153, in wrapper
    result, success = func(*args, **kwargs)
  File "C:\Users\sreej\AppData\Local\Programs\Python\Python310\lib\site-packages\dbt\cli\requires.py", line 103, in wrapper
    return func(*args, **kwargs)
  File "C:\Users\sreej\AppData\Local\Programs\Python\Python310\lib\site-packages\dbt\cli\main.py", line 477, in init
    results = task.run()
  File "C:\Users\sreej\AppData\Local\Programs\Python\Python310\lib\site-packages\dbt\task\init.py", line 346, in run
    self.setup_profile(profile_name)
  File "C:\Users\sreej\AppData\Local\Programs\Python\Python310\lib\site-packages\dbt\task\init.py", line 262, in setup_profile
    self.create_profile_from_target(adapter, profile_name=profile_name)
  File "C:\Users\sreej\AppData\Local\Programs\Python\Python310\lib\site-packages\dbt\task\init.py", line 179, in create_profile_from_target
    self.create_profile_from_profile_template(profile_template, profile_name)
  File "C:\Users\sreej\AppData\Local\Programs\Python\Python310\lib\site-packages\dbt\task\init.py", line 163, in create_profile_from_profile_template
    target = self.generate_target_from_input(prompts, initial_target)
  File "C:\Users\sreej\AppData\Local\Programs\Python\Python310\lib\site-packages\dbt\task\init.py", line 113, in generate_target_from_input
    numeric_choice = click.prompt(prompt_msg, type=click.INT)
  File "C:\Users\sreej\AppData\Local\Programs\Python\Python310\lib\site-packages\click\termui.py", line 164, in prompt
    value = prompt_func(prompt)
  File "C:\Users\sreej\AppData\Local\Programs\Python\Python310\lib\site-packages\click\termui.py", line 147, in prompt_func
    raise Abort() from None
click.exceptions.Abort

[0m18:33:03.673049 [debug] [MainThread]: Command `dbt init` failed at 18:33:03.673049 after 11.03 seconds
[0m18:33:03.673049 [debug] [MainThread]: Sending event: {'category': 'dbt', 'action': 'invocation', 'label': 'end', 'context': [<snowplow_tracker.self_describing_json.SelfDescribingJson object at 0x000001365D9F0A90>, <snowplow_tracker.self_describing_json.SelfDescribingJson object at 0x00000136709F36A0>, <snowplow_tracker.self_describing_json.SelfDescribingJson object at 0x00000136709F1D20>]}
[0m18:33:03.674504 [debug] [MainThread]: Flushing usage events
[0m18:33:03.886757 [debug] [MainThread]: An error was encountered while trying to flush usage events
[0m18:36:58.973305 [debug] [MainThread]: Sending event: {'category': 'dbt', 'action': 'invocation', 'label': 'start', 'context': [<snowplow_tracker.self_describing_json.SelfDescribingJson object at 0x000002320AD84A30>, <snowplow_tracker.self_describing_json.SelfDescribingJson object at 0x000002320CC513F0>, <snowplow_tracker.self_describing_json.SelfDescribingJson object at 0x000002320CC51210>]}


============================== 18:36:58.985899 | b77e80a1-6232-4d6a-964f-3b95d625470a ==============================
[0m18:36:58.985899 [info ] [MainThread]: Running with dbt=1.9.2
[0m18:36:58.986404 [debug] [MainThread]: running dbt with arguments {'printer_width': '80', 'indirect_selection': 'eager', 'write_json': 'True', 'log_cache_events': 'False', 'partial_parse': 'True', 'cache_selected_only': 'False', 'profiles_dir': 'C:\\Users\\sreej\\.dbt', 'version_check': 'True', 'fail_fast': 'False', 'log_path': 'logs', 'debug': 'False', 'warn_error': 'None', 'use_colors': 'True', 'use_experimental_parser': 'False', 'no_print': 'None', 'quiet': 'False', 'empty': 'False', 'warn_error_options': 'WarnErrorOptions(include=[], exclude=[])', 'introspect': 'True', 'static_parser': 'True', 'invocation_command': 'dbt run', 'target_path': 'None', 'log_format': 'default', 'send_anonymous_usage_stats': 'True'}
[0m18:36:58.986404 [error] [MainThread]: Encountered an error:
Runtime Error
  No dbt_project.yml found at expected path C:\Users\sreej\.dbt\dbt_project.yml
  Verify that each entry within packages.yml (and their transitive dependencies) contains a file named dbt_project.yml
  
[0m18:36:58.986404 [debug] [MainThread]: Command `dbt run` failed at 18:36:58.986404 after 0.07 seconds
[0m18:36:58.986404 [debug] [MainThread]: Sending event: {'category': 'dbt', 'action': 'invocation', 'label': 'end', 'context': [<snowplow_tracker.self_describing_json.SelfDescribingJson object at 0x000002320AD84A30>, <snowplow_tracker.self_describing_json.SelfDescribingJson object at 0x000002320CC51210>, <snowplow_tracker.self_describing_json.SelfDescribingJson object at 0x000002320CC514B0>]}
[0m18:36:58.986404 [debug] [MainThread]: Flushing usage events
[0m18:36:59.189434 [debug] [MainThread]: An error was encountered while trying to flush usage events
[0m11:50:05.684448 [debug] [MainThread]: Sending event: {'category': 'dbt', 'action': 'invocation', 'label': 'start', 'context': [<snowplow_tracker.self_describing_json.SelfDescribingJson object at 0x000001D94EDF0AC0>, <snowplow_tracker.self_describing_json.SelfDescribingJson object at 0x000001D950CCAA10>, <snowplow_tracker.self_describing_json.SelfDescribingJson object at 0x000001D950CCA830>]}


============================== 11:50:05.700073 | 0c14b3d4-75ed-4e02-b321-6b8bc5ab483d ==============================
[0m11:50:05.700073 [info ] [MainThread]: Running with dbt=1.9.2
[0m11:50:05.704581 [debug] [MainThread]: running dbt with arguments {'printer_width': '80', 'indirect_selection': 'eager', 'write_json': 'True', 'log_cache_events': 'False', 'partial_parse': 'True', 'cache_selected_only': 'False', 'profiles_dir': 'C:\\Users\\sreej\\.dbt', 'version_check': 'True', 'fail_fast': 'False', 'log_path': 'logs', 'debug': 'False', 'warn_error': 'None', 'use_colors': 'True', 'use_experimental_parser': 'False', 'empty': 'False', 'quiet': 'False', 'no_print': 'None', 'log_format': 'default', 'introspect': 'True', 'invocation_command': 'dbt run --models newsletter_clean', 'warn_error_options': 'WarnErrorOptions(include=[], exclude=[])', 'target_path': 'None', 'static_parser': 'True', 'send_anonymous_usage_stats': 'True'}
[0m11:50:05.704581 [error] [MainThread]: Encountered an error:
Runtime Error
  No dbt_project.yml found at expected path C:\Users\sreej\.dbt\dbt_project.yml
  Verify that each entry within packages.yml (and their transitive dependencies) contains a file named dbt_project.yml
  
[0m11:50:05.704581 [debug] [MainThread]: Command `dbt run` failed at 11:50:05.704581 after 0.10 seconds
[0m11:50:05.704581 [debug] [MainThread]: Sending event: {'category': 'dbt', 'action': 'invocation', 'label': 'end', 'context': [<snowplow_tracker.self_describing_json.SelfDescribingJson object at 0x000001D94EDF0AC0>, <snowplow_tracker.self_describing_json.SelfDescribingJson object at 0x000001D950CCA830>, <snowplow_tracker.self_describing_json.SelfDescribingJson object at 0x000001D950CCAAD0>]}
[0m11:50:05.704581 [debug] [MainThread]: Flushing usage events
[0m11:50:06.553446 [debug] [MainThread]: An error was encountered while trying to flush usage events
[0m12:04:09.174813 [debug] [MainThread]: Sending event: {'category': 'dbt', 'action': 'invocation', 'label': 'start', 'context': [<snowplow_tracker.self_describing_json.SelfDescribingJson object at 0x00000248BAA54A00>, <snowplow_tracker.self_describing_json.SelfDescribingJson object at 0x00000248BC91D420>, <snowplow_tracker.self_describing_json.SelfDescribingJson object at 0x00000248BC91D240>]}


============================== 12:04:09.178868 | 2bceb0e8-7491-4800-9884-c4c02a58c1b7 ==============================
[0m12:04:09.178868 [info ] [MainThread]: Running with dbt=1.9.2
[0m12:04:09.178868 [debug] [MainThread]: running dbt with arguments {'printer_width': '80', 'indirect_selection': 'eager', 'write_json': 'True', 'log_cache_events': 'False', 'partial_parse': 'True', 'cache_selected_only': 'False', 'profiles_dir': 'C:\\Users\\sreej\\.dbt', 'fail_fast': 'False', 'debug': 'False', 'log_path': 'logs', 'version_check': 'True', 'warn_error': 'None', 'use_colors': 'True', 'use_experimental_parser': 'False', 'no_print': 'None', 'quiet': 'False', 'empty': 'False', 'warn_error_options': 'WarnErrorOptions(include=[], exclude=[])', 'invocation_command': 'dbt run --models newsletter_clean', 'log_format': 'default', 'static_parser': 'True', 'target_path': 'None', 'introspect': 'True', 'send_anonymous_usage_stats': 'True'}
[0m12:04:09.178868 [error] [MainThread]: Encountered an error:
Runtime Error
  No dbt_project.yml found at expected path C:\Users\sreej\.dbt\dbt_project.yml
  Verify that each entry within packages.yml (and their transitive dependencies) contains a file named dbt_project.yml
  
[0m12:04:09.186289 [debug] [MainThread]: Command `dbt run` failed at 12:04:09.186289 after 0.09 seconds
[0m12:04:09.186289 [debug] [MainThread]: Sending event: {'category': 'dbt', 'action': 'invocation', 'label': 'end', 'context': [<snowplow_tracker.self_describing_json.SelfDescribingJson object at 0x00000248BAA54A00>, <snowplow_tracker.self_describing_json.SelfDescribingJson object at 0x00000248BC91D240>, <snowplow_tracker.self_describing_json.SelfDescribingJson object at 0x00000248BC91D4E0>]}
[0m12:04:09.186289 [debug] [MainThread]: Flushing usage events
[0m12:04:09.696411 [debug] [MainThread]: An error was encountered while trying to flush usage events
