[2025-02-12T23:15:49.679+0000] {local_task_job_runner.py:123} INFO - ::group::Pre task execution logs
[2025-02-12T23:15:49.698+0000] {taskinstance.py:2614} INFO - Dependencies all met for dep_context=non-requeueable deps ti=<TaskInstance: zip_csv_ingestion.upload_to_gcs manual__2025-02-12T23:01:04.521230+00:00 [queued]>
[2025-02-12T23:15:49.706+0000] {taskinstance.py:2614} INFO - Dependencies all met for dep_context=requeueable deps ti=<TaskInstance: zip_csv_ingestion.upload_to_gcs manual__2025-02-12T23:01:04.521230+00:00 [queued]>
[2025-02-12T23:15:49.706+0000] {taskinstance.py:2867} INFO - Starting attempt 4 of 4
[2025-02-12T23:15:49.717+0000] {taskinstance.py:2890} INFO - Executing <Task(LocalFilesystemToGCSOperator): upload_to_gcs> on 2025-02-12 23:01:04.521230+00:00
[2025-02-12T23:15:49.726+0000] {warnings.py:112} WARNING - /home/***/.local/lib/python3.12/site-packages/***/task/task_runner/standard_task_runner.py:70: DeprecationWarning: This process (pid=277) is multi-threaded, use of fork() may lead to deadlocks in the child.
  pid = os.fork()

[2025-02-12T23:15:49.728+0000] {standard_task_runner.py:72} INFO - Started process 279 to run task
[2025-02-12T23:15:49.728+0000] {standard_task_runner.py:104} INFO - Running: ['***', 'tasks', 'run', 'zip_csv_ingestion', 'upload_to_gcs', 'manual__2025-02-12T23:01:04.521230+00:00', '--job-id', '38', '--raw', '--subdir', 'DAGS_FOLDER/csv_to_gcs.py', '--cfg-path', '/tmp/tmpuv4ucrj2']
[2025-02-12T23:15:49.729+0000] {standard_task_runner.py:105} INFO - Job 38: Subtask upload_to_gcs
[2025-02-12T23:15:49.769+0000] {task_command.py:467} INFO - Running <TaskInstance: zip_csv_ingestion.upload_to_gcs manual__2025-02-12T23:01:04.521230+00:00 [running]> on host d402094725ac
[2025-02-12T23:15:49.846+0000] {taskinstance.py:3134} INFO - Exporting env vars: AIRFLOW_CTX_DAG_OWNER='***' AIRFLOW_CTX_DAG_ID='zip_csv_ingestion' AIRFLOW_CTX_TASK_ID='upload_to_gcs' AIRFLOW_CTX_EXECUTION_DATE='2025-02-12T23:01:04.521230+00:00' AIRFLOW_CTX_TRY_NUMBER='4' AIRFLOW_CTX_DAG_RUN_ID='manual__2025-02-12T23:01:04.521230+00:00'
[2025-02-12T23:15:49.847+0000] {logging_mixin.py:190} INFO - Task instance is in running state
[2025-02-12T23:15:49.847+0000] {logging_mixin.py:190} INFO -  Previous state of the Task instance: queued
[2025-02-12T23:15:49.848+0000] {logging_mixin.py:190} INFO - Current task name:upload_to_gcs state:running start_date:2025-02-12 23:15:49.698317+00:00
[2025-02-12T23:15:49.848+0000] {logging_mixin.py:190} INFO - Dag name:zip_csv_ingestion and current dag run status:running
[2025-02-12T23:15:49.849+0000] {taskinstance.py:732} INFO - ::endgroup::
[2025-02-12T23:15:49.866+0000] {taskinstance.py:3313} ERROR - Task failed with exception
Traceback (most recent call last):
  File "/home/airflow/.local/lib/python3.12/site-packages/airflow/models/taskinstance.py", line 768, in _execute_task
    result = _execute_callable(context=context, **execute_callable_kwargs)
             ^^^^^^^^^^^^^^^^^^^^^^^^^^^^^^^^^^^^^^^^^^^^^^^^^^^^^^^^^^^^^
  File "/home/airflow/.local/lib/python3.12/site-packages/airflow/models/taskinstance.py", line 734, in _execute_callable
    return ExecutionCallableRunner(
           ^^^^^^^^^^^^^^^^^^^^^^^^
  File "/home/airflow/.local/lib/python3.12/site-packages/airflow/utils/operator_helpers.py", line 252, in run
    return self.func(*args, **kwargs)
           ^^^^^^^^^^^^^^^^^^^^^^^^^^
  File "/home/airflow/.local/lib/python3.12/site-packages/airflow/models/baseoperator.py", line 424, in wrapper
    return func(self, *args, **kwargs)
           ^^^^^^^^^^^^^^^^^^^^^^^^^^^
  File "/home/airflow/.local/lib/python3.12/site-packages/airflow/providers/google/cloud/transfers/local_to_gcs.py", line 95, in execute
    hook = GCSHook(
           ^^^^^^^^
  File "/home/airflow/.local/lib/python3.12/site-packages/airflow/providers/google/common/hooks/base_google.py", line 283, in __init__
    self.extras: dict = self.get_connection(self.gcp_conn_id).extra_dejson
                        ^^^^^^^^^^^^^^^^^^^^^^^^^^^^^^^^^^^^^
  File "/home/airflow/.local/lib/python3.12/site-packages/airflow/hooks/base.py", line 83, in get_connection
    conn = Connection.get_connection_from_secrets(conn_id)
           ^^^^^^^^^^^^^^^^^^^^^^^^^^^^^^^^^^^^^^^^^^^^^^^
  File "/home/airflow/.local/lib/python3.12/site-packages/airflow/models/connection.py", line 537, in get_connection_from_secrets
    raise AirflowNotFoundException(f"The conn_id `{conn_id}` isn't defined")
airflow.exceptions.AirflowNotFoundException: The conn_id `google_cloud_default` isn't defined
[2025-02-12T23:15:49.876+0000] {logging_mixin.py:190} INFO - Task instance in failure state
[2025-02-12T23:15:49.876+0000] {logging_mixin.py:190} INFO - Task start:2025-02-12 23:15:49.698317+00:00 end:2025-02-12 23:15:49.875792+00:00 duration:0.177475
[2025-02-12T23:15:49.876+0000] {logging_mixin.py:190} INFO - Task:<Task(LocalFilesystemToGCSOperator): upload_to_gcs> dag:<DAG: zip_csv_ingestion> dagrun:<DagRun zip_csv_ingestion @ 2025-02-12 23:01:04.521230+00:00: manual__2025-02-12T23:01:04.521230+00:00, state:running, queued_at: 2025-02-12 23:01:04.537330+00:00. externally triggered: True>
[2025-02-12T23:15:49.877+0000] {logging_mixin.py:190} INFO - Failure caused by The conn_id `google_cloud_default` isn't defined
[2025-02-12T23:15:49.877+0000] {taskinstance.py:1226} INFO - Marking task as FAILED. dag_id=zip_csv_ingestion, task_id=upload_to_gcs, run_id=manual__2025-02-12T23:01:04.521230+00:00, execution_date=20250212T230104, start_date=20250212T231549, end_date=20250212T231549
[2025-02-12T23:15:50.101+0000] {taskinstance.py:341} INFO - ::group::Post task execution logs
[2025-02-12T23:15:50.101+0000] {standard_task_runner.py:124} ERROR - Failed to execute job 38 for task upload_to_gcs (The conn_id `google_cloud_default` isn't defined; 279)
Traceback (most recent call last):
  File "/home/airflow/.local/lib/python3.12/site-packages/airflow/task/task_runner/standard_task_runner.py", line 117, in _start_by_fork
    ret = args.func(args, dag=self.dag)
          ^^^^^^^^^^^^^^^^^^^^^^^^^^^^^
  File "/home/airflow/.local/lib/python3.12/site-packages/airflow/cli/cli_config.py", line 49, in command
    return func(*args, **kwargs)
           ^^^^^^^^^^^^^^^^^^^^^
  File "/home/airflow/.local/lib/python3.12/site-packages/airflow/utils/cli.py", line 116, in wrapper
    return f(*args, **kwargs)
           ^^^^^^^^^^^^^^^^^^
  File "/home/airflow/.local/lib/python3.12/site-packages/airflow/cli/commands/task_command.py", line 483, in task_run
    task_return_code = _run_task_by_selected_method(args, _dag, ti)
                       ^^^^^^^^^^^^^^^^^^^^^^^^^^^^^^^^^^^^^^^^^^^^
  File "/home/airflow/.local/lib/python3.12/site-packages/airflow/cli/commands/task_command.py", line 256, in _run_task_by_selected_method
    return _run_raw_task(args, ti)
           ^^^^^^^^^^^^^^^^^^^^^^^
  File "/home/airflow/.local/lib/python3.12/site-packages/airflow/cli/commands/task_command.py", line 341, in _run_raw_task
    return ti._run_raw_task(
           ^^^^^^^^^^^^^^^^^
  File "/home/airflow/.local/lib/python3.12/site-packages/airflow/utils/session.py", line 97, in wrapper
    return func(*args, session=session, **kwargs)
           ^^^^^^^^^^^^^^^^^^^^^^^^^^^^^^^^^^^^^^
  File "/home/airflow/.local/lib/python3.12/site-packages/airflow/models/taskinstance.py", line 3006, in _run_raw_task
    return _run_raw_task(
           ^^^^^^^^^^^^^^
  File "/home/airflow/.local/lib/python3.12/site-packages/airflow/models/taskinstance.py", line 274, in _run_raw_task
    TaskInstance._execute_task_with_callbacks(
  File "/home/airflow/.local/lib/python3.12/site-packages/airflow/models/taskinstance.py", line 3161, in _execute_task_with_callbacks
    result = self._execute_task(context, task_orig)
             ^^^^^^^^^^^^^^^^^^^^^^^^^^^^^^^^^^^^^^
  File "/home/airflow/.local/lib/python3.12/site-packages/airflow/models/taskinstance.py", line 3185, in _execute_task
    return _execute_task(self, context, task_orig)
           ^^^^^^^^^^^^^^^^^^^^^^^^^^^^^^^^^^^^^^^
  File "/home/airflow/.local/lib/python3.12/site-packages/airflow/models/taskinstance.py", line 768, in _execute_task
    result = _execute_callable(context=context, **execute_callable_kwargs)
             ^^^^^^^^^^^^^^^^^^^^^^^^^^^^^^^^^^^^^^^^^^^^^^^^^^^^^^^^^^^^^
  File "/home/airflow/.local/lib/python3.12/site-packages/airflow/models/taskinstance.py", line 734, in _execute_callable
    return ExecutionCallableRunner(
           ^^^^^^^^^^^^^^^^^^^^^^^^
  File "/home/airflow/.local/lib/python3.12/site-packages/airflow/utils/operator_helpers.py", line 252, in run
    return self.func(*args, **kwargs)
           ^^^^^^^^^^^^^^^^^^^^^^^^^^
  File "/home/airflow/.local/lib/python3.12/site-packages/airflow/models/baseoperator.py", line 424, in wrapper
    return func(self, *args, **kwargs)
           ^^^^^^^^^^^^^^^^^^^^^^^^^^^
  File "/home/airflow/.local/lib/python3.12/site-packages/airflow/providers/google/cloud/transfers/local_to_gcs.py", line 95, in execute
    hook = GCSHook(
           ^^^^^^^^
  File "/home/airflow/.local/lib/python3.12/site-packages/airflow/providers/google/common/hooks/base_google.py", line 283, in __init__
    self.extras: dict = self.get_connection(self.gcp_conn_id).extra_dejson
                        ^^^^^^^^^^^^^^^^^^^^^^^^^^^^^^^^^^^^^
  File "/home/airflow/.local/lib/python3.12/site-packages/airflow/hooks/base.py", line 83, in get_connection
    conn = Connection.get_connection_from_secrets(conn_id)
           ^^^^^^^^^^^^^^^^^^^^^^^^^^^^^^^^^^^^^^^^^^^^^^^
  File "/home/airflow/.local/lib/python3.12/site-packages/airflow/models/connection.py", line 537, in get_connection_from_secrets
    raise AirflowNotFoundException(f"The conn_id `{conn_id}` isn't defined")
airflow.exceptions.AirflowNotFoundException: The conn_id `google_cloud_default` isn't defined
[2025-02-12T23:15:50.149+0000] {local_task_job_runner.py:266} INFO - Task exited with return code 1
[2025-02-12T23:15:50.164+0000] {taskinstance.py:3901} INFO - 0 downstream tasks scheduled from follow-on schedule check
[2025-02-12T23:15:50.165+0000] {local_task_job_runner.py:245} INFO - ::endgroup::
