[2025-02-12T23:45:41.898+0000] {local_task_job_runner.py:123} INFO - ::group::Pre task execution logs
[2025-02-12T23:45:41.915+0000] {taskinstance.py:2614} INFO - Dependencies all met for dep_context=non-requeueable deps ti=<TaskInstance: zip_csv_ingestion.upload_to_gcs manual__2025-02-12T23:35:50.048760+00:00 [queued]>
[2025-02-12T23:45:41.924+0000] {taskinstance.py:2614} INFO - Dependencies all met for dep_context=requeueable deps ti=<TaskInstance: zip_csv_ingestion.upload_to_gcs manual__2025-02-12T23:35:50.048760+00:00 [queued]>
[2025-02-12T23:45:41.924+0000] {taskinstance.py:2867} INFO - Starting attempt 2 of 2
[2025-02-12T23:45:41.935+0000] {taskinstance.py:2890} INFO - Executing <Task(LocalFilesystemToGCSOperator): upload_to_gcs> on 2025-02-12 23:35:50.048760+00:00
[2025-02-12T23:45:41.944+0000] {warnings.py:112} WARNING - /home/***/.local/lib/python3.12/site-packages/***/task/task_runner/standard_task_runner.py:70: DeprecationWarning: This process (pid=58) is multi-threaded, use of fork() may lead to deadlocks in the child.
  pid = os.fork()

[2025-02-12T23:45:41.945+0000] {standard_task_runner.py:72} INFO - Started process 60 to run task
[2025-02-12T23:45:41.946+0000] {standard_task_runner.py:104} INFO - Running: ['***', 'tasks', 'run', 'zip_csv_ingestion', 'upload_to_gcs', 'manual__2025-02-12T23:35:50.048760+00:00', '--job-id', '45', '--raw', '--subdir', 'DAGS_FOLDER/csv_to_gcs.py', '--cfg-path', '/tmp/tmpvh6d4swp']
[2025-02-12T23:45:41.947+0000] {standard_task_runner.py:105} INFO - Job 45: Subtask upload_to_gcs
[2025-02-12T23:45:41.985+0000] {task_command.py:467} INFO - Running <TaskInstance: zip_csv_ingestion.upload_to_gcs manual__2025-02-12T23:35:50.048760+00:00 [running]> on host a372cb7e503c
[2025-02-12T23:45:42.047+0000] {taskinstance.py:3134} INFO - Exporting env vars: AIRFLOW_CTX_DAG_OWNER='***' AIRFLOW_CTX_DAG_ID='zip_csv_ingestion' AIRFLOW_CTX_TASK_ID='upload_to_gcs' AIRFLOW_CTX_EXECUTION_DATE='2025-02-12T23:35:50.048760+00:00' AIRFLOW_CTX_TRY_NUMBER='2' AIRFLOW_CTX_DAG_RUN_ID='manual__2025-02-12T23:35:50.048760+00:00'
[2025-02-12T23:45:42.049+0000] {logging_mixin.py:190} INFO - Task instance is in running state
[2025-02-12T23:45:42.049+0000] {logging_mixin.py:190} INFO -  Previous state of the Task instance: queued
[2025-02-12T23:45:42.049+0000] {logging_mixin.py:190} INFO - Current task name:upload_to_gcs state:running start_date:2025-02-12 23:45:41.916241+00:00
[2025-02-12T23:45:42.049+0000] {logging_mixin.py:190} INFO - Dag name:zip_csv_ingestion and current dag run status:running
[2025-02-12T23:45:42.050+0000] {taskinstance.py:732} INFO - ::endgroup::
[2025-02-12T23:45:42.057+0000] {connection.py:277} WARNING - Connection schemes (type: google_cloud_platform) shall not contain '_' according to RFC3986.
[2025-02-12T23:45:42.059+0000] {base.py:84} INFO - Retrieving connection 'google_cloud_default'
[2025-02-12T23:45:42.069+0000] {taskinstance.py:3313} ERROR - Task failed with exception
Traceback (most recent call last):
  File "/home/airflow/.local/lib/python3.12/site-packages/airflow/providers/google/common/hooks/base_google.py", line 300, in get_credentials_and_project_id
    keyfile_dict_json = json.loads(keyfile_dict)
                        ^^^^^^^^^^^^^^^^^^^^^^^^
  File "/usr/local/lib/python3.12/json/__init__.py", line 346, in loads
    return _default_decoder.decode(s)
           ^^^^^^^^^^^^^^^^^^^^^^^^^^
  File "/usr/local/lib/python3.12/json/decoder.py", line 338, in decode
    obj, end = self.raw_decode(s, idx=_w(s, 0).end())
               ^^^^^^^^^^^^^^^^^^^^^^^^^^^^^^^^^^^^^^
  File "/usr/local/lib/python3.12/json/decoder.py", line 356, in raw_decode
    raise JSONDecodeError("Expecting value", s, err.value) from None
json.decoder.JSONDecodeError: Expecting value: line 1 column 1 (char 0)

During handling of the above exception, another exception occurred:

Traceback (most recent call last):
  File "/home/airflow/.local/lib/python3.12/site-packages/airflow/models/taskinstance.py", line 768, in _execute_task
    result = _execute_callable(context=context, **execute_callable_kwargs)
             ^^^^^^^^^^^^^^^^^^^^^^^^^^^^^^^^^^^^^^^^^^^^^^^^^^^^^^^^^^^^^
  File "/home/airflow/.local/lib/python3.12/site-packages/airflow/models/taskinstance.py", line 734, in _execute_callable
    return ExecutionCallableRunner(
           ^^^^^^^^^^^^^^^^^^^^^^^^
  File "/home/airflow/.local/lib/python3.12/site-packages/airflow/utils/operator_helpers.py", line 252, in run
    return self.func(*args, **kwargs)
           ^^^^^^^^^^^^^^^^^^^^^^^^^^
  File "/home/airflow/.local/lib/python3.12/site-packages/airflow/models/baseoperator.py", line 424, in wrapper
    return func(self, *args, **kwargs)
           ^^^^^^^^^^^^^^^^^^^^^^^^^^^
  File "/home/airflow/.local/lib/python3.12/site-packages/airflow/providers/google/cloud/transfers/local_to_gcs.py", line 115, in execute
    hook.upload(
  File "/home/airflow/.local/lib/python3.12/site-packages/airflow/providers/google/cloud/hooks/gcs.py", line 543, in upload
    client = self.get_conn()
             ^^^^^^^^^^^^^^^
  File "/home/airflow/.local/lib/python3.12/site-packages/airflow/providers/google/cloud/hooks/gcs.py", line 159, in get_conn
    credentials=self.get_credentials(), client_info=CLIENT_INFO, project=self.project_id
                ^^^^^^^^^^^^^^^^^^^^^^
  File "/home/airflow/.local/lib/python3.12/site-packages/airflow/providers/google/common/hooks/base_google.py", line 356, in get_credentials
    credentials, _ = self.get_credentials_and_project_id()
                     ^^^^^^^^^^^^^^^^^^^^^^^^^^^^^^^^^^^^^
  File "/home/airflow/.local/lib/python3.12/site-packages/airflow/providers/google/common/hooks/base_google.py", line 302, in get_credentials_and_project_id
    raise AirflowException("Invalid key JSON.")
airflow.exceptions.AirflowException: Invalid key JSON.
[2025-02-12T23:45:42.081+0000] {logging_mixin.py:190} INFO - Task instance in failure state
[2025-02-12T23:45:42.082+0000] {logging_mixin.py:190} INFO - Task start:2025-02-12 23:45:41.916241+00:00 end:2025-02-12 23:45:42.081465+00:00 duration:0.165224
[2025-02-12T23:45:42.082+0000] {logging_mixin.py:190} INFO - Task:<Task(LocalFilesystemToGCSOperator): upload_to_gcs> dag:<DAG: zip_csv_ingestion> dagrun:<DagRun zip_csv_ingestion @ 2025-02-12 23:35:50.048760+00:00: manual__2025-02-12T23:35:50.048760+00:00, state:running, queued_at: 2025-02-12 23:35:50.067847+00:00. externally triggered: True>
[2025-02-12T23:45:42.082+0000] {logging_mixin.py:190} INFO - Failure caused by Invalid key JSON.
[2025-02-12T23:45:42.083+0000] {taskinstance.py:1226} INFO - Marking task as FAILED. dag_id=zip_csv_ingestion, task_id=upload_to_gcs, run_id=manual__2025-02-12T23:35:50.048760+00:00, execution_date=20250212T233550, start_date=20250212T234541, end_date=20250212T234542
[2025-02-12T23:45:42.320+0000] {taskinstance.py:341} INFO - ::group::Post task execution logs
[2025-02-12T23:45:42.321+0000] {standard_task_runner.py:124} ERROR - Failed to execute job 45 for task upload_to_gcs (Invalid key JSON.; 60)
Traceback (most recent call last):
  File "/home/airflow/.local/lib/python3.12/site-packages/airflow/providers/google/common/hooks/base_google.py", line 300, in get_credentials_and_project_id
    keyfile_dict_json = json.loads(keyfile_dict)
                        ^^^^^^^^^^^^^^^^^^^^^^^^
  File "/usr/local/lib/python3.12/json/__init__.py", line 346, in loads
    return _default_decoder.decode(s)
           ^^^^^^^^^^^^^^^^^^^^^^^^^^
  File "/usr/local/lib/python3.12/json/decoder.py", line 338, in decode
    obj, end = self.raw_decode(s, idx=_w(s, 0).end())
               ^^^^^^^^^^^^^^^^^^^^^^^^^^^^^^^^^^^^^^
  File "/usr/local/lib/python3.12/json/decoder.py", line 356, in raw_decode
    raise JSONDecodeError("Expecting value", s, err.value) from None
json.decoder.JSONDecodeError: Expecting value: line 1 column 1 (char 0)

During handling of the above exception, another exception occurred:

Traceback (most recent call last):
  File "/home/airflow/.local/lib/python3.12/site-packages/airflow/task/task_runner/standard_task_runner.py", line 117, in _start_by_fork
    ret = args.func(args, dag=self.dag)
          ^^^^^^^^^^^^^^^^^^^^^^^^^^^^^
  File "/home/airflow/.local/lib/python3.12/site-packages/airflow/cli/cli_config.py", line 49, in command
    return func(*args, **kwargs)
           ^^^^^^^^^^^^^^^^^^^^^
  File "/home/airflow/.local/lib/python3.12/site-packages/airflow/utils/cli.py", line 116, in wrapper
    return f(*args, **kwargs)
           ^^^^^^^^^^^^^^^^^^
  File "/home/airflow/.local/lib/python3.12/site-packages/airflow/cli/commands/task_command.py", line 483, in task_run
    task_return_code = _run_task_by_selected_method(args, _dag, ti)
                       ^^^^^^^^^^^^^^^^^^^^^^^^^^^^^^^^^^^^^^^^^^^^
  File "/home/airflow/.local/lib/python3.12/site-packages/airflow/cli/commands/task_command.py", line 256, in _run_task_by_selected_method
    return _run_raw_task(args, ti)
           ^^^^^^^^^^^^^^^^^^^^^^^
  File "/home/airflow/.local/lib/python3.12/site-packages/airflow/cli/commands/task_command.py", line 341, in _run_raw_task
    return ti._run_raw_task(
           ^^^^^^^^^^^^^^^^^
  File "/home/airflow/.local/lib/python3.12/site-packages/airflow/utils/session.py", line 97, in wrapper
    return func(*args, session=session, **kwargs)
           ^^^^^^^^^^^^^^^^^^^^^^^^^^^^^^^^^^^^^^
  File "/home/airflow/.local/lib/python3.12/site-packages/airflow/models/taskinstance.py", line 3006, in _run_raw_task
    return _run_raw_task(
           ^^^^^^^^^^^^^^
  File "/home/airflow/.local/lib/python3.12/site-packages/airflow/models/taskinstance.py", line 274, in _run_raw_task
    TaskInstance._execute_task_with_callbacks(
  File "/home/airflow/.local/lib/python3.12/site-packages/airflow/models/taskinstance.py", line 3161, in _execute_task_with_callbacks
    result = self._execute_task(context, task_orig)
             ^^^^^^^^^^^^^^^^^^^^^^^^^^^^^^^^^^^^^^
  File "/home/airflow/.local/lib/python3.12/site-packages/airflow/models/taskinstance.py", line 3185, in _execute_task
    return _execute_task(self, context, task_orig)
           ^^^^^^^^^^^^^^^^^^^^^^^^^^^^^^^^^^^^^^^
  File "/home/airflow/.local/lib/python3.12/site-packages/airflow/models/taskinstance.py", line 768, in _execute_task
    result = _execute_callable(context=context, **execute_callable_kwargs)
             ^^^^^^^^^^^^^^^^^^^^^^^^^^^^^^^^^^^^^^^^^^^^^^^^^^^^^^^^^^^^^
  File "/home/airflow/.local/lib/python3.12/site-packages/airflow/models/taskinstance.py", line 734, in _execute_callable
    return ExecutionCallableRunner(
           ^^^^^^^^^^^^^^^^^^^^^^^^
  File "/home/airflow/.local/lib/python3.12/site-packages/airflow/utils/operator_helpers.py", line 252, in run
    return self.func(*args, **kwargs)
           ^^^^^^^^^^^^^^^^^^^^^^^^^^
  File "/home/airflow/.local/lib/python3.12/site-packages/airflow/models/baseoperator.py", line 424, in wrapper
    return func(self, *args, **kwargs)
           ^^^^^^^^^^^^^^^^^^^^^^^^^^^
  File "/home/airflow/.local/lib/python3.12/site-packages/airflow/providers/google/cloud/transfers/local_to_gcs.py", line 115, in execute
    hook.upload(
  File "/home/airflow/.local/lib/python3.12/site-packages/airflow/providers/google/cloud/hooks/gcs.py", line 543, in upload
    client = self.get_conn()
             ^^^^^^^^^^^^^^^
  File "/home/airflow/.local/lib/python3.12/site-packages/airflow/providers/google/cloud/hooks/gcs.py", line 159, in get_conn
    credentials=self.get_credentials(), client_info=CLIENT_INFO, project=self.project_id
                ^^^^^^^^^^^^^^^^^^^^^^
  File "/home/airflow/.local/lib/python3.12/site-packages/airflow/providers/google/common/hooks/base_google.py", line 356, in get_credentials
    credentials, _ = self.get_credentials_and_project_id()
                     ^^^^^^^^^^^^^^^^^^^^^^^^^^^^^^^^^^^^^
  File "/home/airflow/.local/lib/python3.12/site-packages/airflow/providers/google/common/hooks/base_google.py", line 302, in get_credentials_and_project_id
    raise AirflowException("Invalid key JSON.")
airflow.exceptions.AirflowException: Invalid key JSON.
[2025-02-12T23:45:42.372+0000] {local_task_job_runner.py:266} INFO - Task exited with return code 1
[2025-02-12T23:45:42.391+0000] {taskinstance.py:3901} INFO - 0 downstream tasks scheduled from follow-on schedule check
[2025-02-12T23:45:42.392+0000] {local_task_job_runner.py:245} INFO - ::endgroup::
